2025-08-07 12:39:56,599 ERROR scheduler Exception in Enqueue Events for Site mysite.local
Traceback (most recent call last):
  File "/Users/simo/Dev/frappe-bench/apps/frappe/frappe/utils/scheduler.py", line 99, in enqueue_events_for_site
    if is_scheduler_inactive():
  File "/Users/simo/Dev/frappe-bench/apps/frappe/frappe/utils/scheduler.py", line 143, in is_scheduler_inactive
    if is_scheduler_disabled(verbose=verbose):
  File "/Users/simo/Dev/frappe-bench/apps/frappe/frappe/utils/scheduler.py", line 156, in is_scheduler_disabled
    frappe.db.get_single_value("System Settings", "enable_scheduler")
  File "/Users/simo/Dev/frappe-bench/apps/frappe/frappe/database/database.py", line 836, in get_single_value
    ).run()
  File "/Users/simo/Dev/frappe-bench/apps/frappe/frappe/query_builder/utils.py", line 87, in execute_query
    result = frappe.db.sql(query, params, *args, **kwargs)  # nosemgrep
  File "/Users/simo/Dev/frappe-bench/apps/frappe/frappe/database/database.py", line 207, in sql
    self.connect()
  File "/Users/simo/Dev/frappe-bench/apps/frappe/frappe/database/database.py", line 112, in connect
    self._conn: "MariadbConnection" | "PostgresConnection" = self.get_connection()
  File "/Users/simo/Dev/frappe-bench/apps/frappe/frappe/database/mariadb/database.py", line 108, in get_connection
    conn = self._get_connection()
  File "/Users/simo/Dev/frappe-bench/apps/frappe/frappe/database/mariadb/database.py", line 114, in _get_connection
    return self.create_connection()
  File "/Users/simo/Dev/frappe-bench/apps/frappe/frappe/database/mariadb/database.py", line 117, in create_connection
    return pymysql.connect(**self.get_connection_settings())
  File "/Users/simo/Dev/frappe-bench/env/lib/python3.10/site-packages/pymysql/connections.py", line 361, in __init__
    self.connect()
  File "/Users/simo/Dev/frappe-bench/env/lib/python3.10/site-packages/pymysql/connections.py", line 669, in connect
    self._request_authentication()
  File "/Users/simo/Dev/frappe-bench/env/lib/python3.10/site-packages/pymysql/connections.py", line 957, in _request_authentication
    auth_packet = self._read_packet()
  File "/Users/simo/Dev/frappe-bench/env/lib/python3.10/site-packages/pymysql/connections.py", line 775, in _read_packet
    packet.raise_for_error()
  File "/Users/simo/Dev/frappe-bench/env/lib/python3.10/site-packages/pymysql/protocol.py", line 219, in raise_for_error
    err.raise_mysql_exception(self._data)
  File "/Users/simo/Dev/frappe-bench/env/lib/python3.10/site-packages/pymysql/err.py", line 150, in raise_mysql_exception
    raise errorclass(errno, errval)
pymysql.err.OperationalError: (1045, "Access denied for user '_0b0250d68beed0d7'@'localhost' (using password: YES)")
2025-08-07 12:40:56,622 ERROR scheduler Exception in Enqueue Events for Site mysite.local
Traceback (most recent call last):
  File "/Users/simo/Dev/frappe-bench/apps/frappe/frappe/utils/scheduler.py", line 99, in enqueue_events_for_site
    if is_scheduler_inactive():
  File "/Users/simo/Dev/frappe-bench/apps/frappe/frappe/utils/scheduler.py", line 143, in is_scheduler_inactive
    if is_scheduler_disabled(verbose=verbose):
  File "/Users/simo/Dev/frappe-bench/apps/frappe/frappe/utils/scheduler.py", line 156, in is_scheduler_disabled
    frappe.db.get_single_value("System Settings", "enable_scheduler")
  File "/Users/simo/Dev/frappe-bench/apps/frappe/frappe/database/database.py", line 836, in get_single_value
    ).run()
  File "/Users/simo/Dev/frappe-bench/apps/frappe/frappe/query_builder/utils.py", line 87, in execute_query
    result = frappe.db.sql(query, params, *args, **kwargs)  # nosemgrep
  File "/Users/simo/Dev/frappe-bench/apps/frappe/frappe/database/database.py", line 207, in sql
    self.connect()
  File "/Users/simo/Dev/frappe-bench/apps/frappe/frappe/database/database.py", line 112, in connect
    self._conn: "MariadbConnection" | "PostgresConnection" = self.get_connection()
  File "/Users/simo/Dev/frappe-bench/apps/frappe/frappe/database/mariadb/database.py", line 108, in get_connection
    conn = self._get_connection()
  File "/Users/simo/Dev/frappe-bench/apps/frappe/frappe/database/mariadb/database.py", line 114, in _get_connection
    return self.create_connection()
  File "/Users/simo/Dev/frappe-bench/apps/frappe/frappe/database/mariadb/database.py", line 117, in create_connection
    return pymysql.connect(**self.get_connection_settings())
  File "/Users/simo/Dev/frappe-bench/env/lib/python3.10/site-packages/pymysql/connections.py", line 361, in __init__
    self.connect()
  File "/Users/simo/Dev/frappe-bench/env/lib/python3.10/site-packages/pymysql/connections.py", line 669, in connect
    self._request_authentication()
  File "/Users/simo/Dev/frappe-bench/env/lib/python3.10/site-packages/pymysql/connections.py", line 957, in _request_authentication
    auth_packet = self._read_packet()
  File "/Users/simo/Dev/frappe-bench/env/lib/python3.10/site-packages/pymysql/connections.py", line 775, in _read_packet
    packet.raise_for_error()
  File "/Users/simo/Dev/frappe-bench/env/lib/python3.10/site-packages/pymysql/protocol.py", line 219, in raise_for_error
    err.raise_mysql_exception(self._data)
  File "/Users/simo/Dev/frappe-bench/env/lib/python3.10/site-packages/pymysql/err.py", line 150, in raise_mysql_exception
    raise errorclass(errno, errval)
pymysql.err.OperationalError: (1045, "Access denied for user '_0b0250d68beed0d7'@'localhost' (using password: YES)")
2025-08-07 12:41:56,630 ERROR scheduler Exception in Enqueue Events for Site mysite.local
Traceback (most recent call last):
  File "/Users/simo/Dev/frappe-bench/apps/frappe/frappe/utils/scheduler.py", line 99, in enqueue_events_for_site
    if is_scheduler_inactive():
  File "/Users/simo/Dev/frappe-bench/apps/frappe/frappe/utils/scheduler.py", line 143, in is_scheduler_inactive
    if is_scheduler_disabled(verbose=verbose):
  File "/Users/simo/Dev/frappe-bench/apps/frappe/frappe/utils/scheduler.py", line 156, in is_scheduler_disabled
    frappe.db.get_single_value("System Settings", "enable_scheduler")
  File "/Users/simo/Dev/frappe-bench/apps/frappe/frappe/database/database.py", line 836, in get_single_value
    ).run()
  File "/Users/simo/Dev/frappe-bench/apps/frappe/frappe/query_builder/utils.py", line 87, in execute_query
    result = frappe.db.sql(query, params, *args, **kwargs)  # nosemgrep
  File "/Users/simo/Dev/frappe-bench/apps/frappe/frappe/database/database.py", line 207, in sql
    self.connect()
  File "/Users/simo/Dev/frappe-bench/apps/frappe/frappe/database/database.py", line 112, in connect
    self._conn: "MariadbConnection" | "PostgresConnection" = self.get_connection()
  File "/Users/simo/Dev/frappe-bench/apps/frappe/frappe/database/mariadb/database.py", line 108, in get_connection
    conn = self._get_connection()
  File "/Users/simo/Dev/frappe-bench/apps/frappe/frappe/database/mariadb/database.py", line 114, in _get_connection
    return self.create_connection()
  File "/Users/simo/Dev/frappe-bench/apps/frappe/frappe/database/mariadb/database.py", line 117, in create_connection
    return pymysql.connect(**self.get_connection_settings())
  File "/Users/simo/Dev/frappe-bench/env/lib/python3.10/site-packages/pymysql/connections.py", line 361, in __init__
    self.connect()
  File "/Users/simo/Dev/frappe-bench/env/lib/python3.10/site-packages/pymysql/connections.py", line 669, in connect
    self._request_authentication()
  File "/Users/simo/Dev/frappe-bench/env/lib/python3.10/site-packages/pymysql/connections.py", line 957, in _request_authentication
    auth_packet = self._read_packet()
  File "/Users/simo/Dev/frappe-bench/env/lib/python3.10/site-packages/pymysql/connections.py", line 775, in _read_packet
    packet.raise_for_error()
  File "/Users/simo/Dev/frappe-bench/env/lib/python3.10/site-packages/pymysql/protocol.py", line 219, in raise_for_error
    err.raise_mysql_exception(self._data)
  File "/Users/simo/Dev/frappe-bench/env/lib/python3.10/site-packages/pymysql/err.py", line 150, in raise_mysql_exception
    raise errorclass(errno, errval)
pymysql.err.OperationalError: (1045, "Access denied for user '_0b0250d68beed0d7'@'localhost' (using password: YES)")
2025-08-14 09:30:17,364 ERROR scheduler Exception in Enqueue Events for Site mysite.local
Traceback (most recent call last):
  File "/Users/simo/Dev/frappe-bench/apps/frappe/frappe/utils/scheduler.py", line 99, in enqueue_events_for_site
    if is_scheduler_inactive():
  File "/Users/simo/Dev/frappe-bench/apps/frappe/frappe/utils/scheduler.py", line 143, in is_scheduler_inactive
    if is_scheduler_disabled(verbose=verbose):
  File "/Users/simo/Dev/frappe-bench/apps/frappe/frappe/utils/scheduler.py", line 156, in is_scheduler_disabled
    frappe.db.get_single_value("System Settings", "enable_scheduler")
  File "/Users/simo/Dev/frappe-bench/apps/frappe/frappe/database/database.py", line 836, in get_single_value
    ).run()
  File "/Users/simo/Dev/frappe-bench/apps/frappe/frappe/query_builder/utils.py", line 87, in execute_query
    result = frappe.db.sql(query, params, *args, **kwargs)  # nosemgrep
  File "/Users/simo/Dev/frappe-bench/apps/frappe/frappe/database/database.py", line 230, in sql
    self._cursor.execute(query, values)
  File "/Users/simo/Dev/frappe-bench/env/lib/python3.10/site-packages/pymysql/cursors.py", line 153, in execute
    result = self._query(query)
  File "/Users/simo/Dev/frappe-bench/env/lib/python3.10/site-packages/pymysql/cursors.py", line 322, in _query
    conn.query(q)
  File "/Users/simo/Dev/frappe-bench/env/lib/python3.10/site-packages/pymysql/connections.py", line 563, in query
    self._affected_rows = self._read_query_result(unbuffered=unbuffered)
  File "/Users/simo/Dev/frappe-bench/env/lib/python3.10/site-packages/pymysql/connections.py", line 825, in _read_query_result
    result.read()
  File "/Users/simo/Dev/frappe-bench/env/lib/python3.10/site-packages/pymysql/connections.py", line 1199, in read
    first_packet = self.connection._read_packet()
  File "/Users/simo/Dev/frappe-bench/env/lib/python3.10/site-packages/pymysql/connections.py", line 775, in _read_packet
    packet.raise_for_error()
  File "/Users/simo/Dev/frappe-bench/env/lib/python3.10/site-packages/pymysql/protocol.py", line 219, in raise_for_error
    err.raise_mysql_exception(self._data)
  File "/Users/simo/Dev/frappe-bench/env/lib/python3.10/site-packages/pymysql/err.py", line 150, in raise_mysql_exception
    raise errorclass(errno, errval)
pymysql.err.ProgrammingError: (1146, "Table '_0b0250d68beed0d7.tabsingles' doesn't exist")
